Workbook

Sheet Returns_Data
A1: return_id | B1: order_id | C1: return_date | D1: return_reason | E1: return_status | F1: refund_amount | G1: reverse_shipping_cost | H1: restocking_loss | I1: Product ID | J1: Product Category | K1: Customer ID
A2: 700001 | B2: 900008 | C2: 45431 | D2: Wrong Item Delivered | E2: Approved | F2: 1130 | G2: 81.79 | H2: 175.15 | I2: =_xlfn.XLOOKUP(B2,Orders_Data!A:A,Orders_Data!C:C,"Not Found") -> 44 | J2: =_xlfn.XLOOKUP(I2,Products_Data!A:A,Products_Data!C:C,"Not Found") -> Accessories | K2: =_xlfn.XLOOKUP(B2,Orders_Data!A:A,Orders_Data!B:B,"Not Found") -> 562
A3: 700002 | B3: 900010 | C3: 45539 | D3: Changed Mind | E3: Approved | F3: 590 | G3: 111.34 | H3: 85.55 | I3: =_xlfn.XLOOKUP(B3,Orders_Data!A:A,Orders_Data!C:C,"Not Found") -> 35 | J3: =_xlfn.XLOOKUP(I3,Products_Data!A:A,Products_Data!C:C,"Not Found") -> Beauty & Personal Care | K3: =_xlfn.XLOOKUP(B3,Orders_Data!A:A,Orders_Data!B:B,"Not Found") -> 36
A4: 700003 | B4: 900011 | C4: 45459 | D4: Changed Mind | E4: Approved | F4: 910 | G4: 111.45 | H4: 141.05 | I4: =_xlfn.XLOOKUP(B4,Orders_Data!A:A,Orders_Data!C:C,"Not Found") -> 43 | J4: =_xlfn.XLOOKUP(I4,Products_Data!A:A,Products_Data!C:C,"Not Found") -> Accessories | K4: =_xlfn.XLOOKUP(B4,Orders_Data!A:A,Orders_Data!B:B,"Not Found") -> 152
A5: 700004 | B5: 900017 | C5: 45625 | D5: Not as Described | E5: Approved | F5: 3170 | G5: 177.27 | H5: 570.6 | I5: =_xlfn.XLOOKUP(B5,Orders_Data!A:A,Orders_Data!C:C,"Not Found") -> 28 | J5: =_xlfn.XLOOKUP(I5,Products_Data!A:A,Products_Data!C:C,"Not Found") -> Home & Kitchen | K5: =_xlfn.XLOOKUP(B5,Orders_Data!A:A,Orders_Data!B:B,"Not Found") -> 107
A6: 700005 | B6: 900024 | C6: 45627 | D6: Changed Mind | E6: Approved | F6: 410 | G6: 78.65 | H6: 59.45 | I6: =_xlfn.XLOOKUP(B6,Orders_Data!A:A,Orders_Data!C:C,"Not Found") -> 34 | J6: =_xlfn.XLOOKUP(I6,Products_Data!A:A,Products_Data!C:C,"Not Found") -> Beauty & Personal Care | K6: =_xlfn.XLOOKUP(B6,Orders_Data!A:A,Orders_Data!B:B,"Not Found") -> 347
A7: 700006 | B7: 900026 | C7: 45516 | D7: Changed Mind | E7: Approved | F7: 3740 | G7: 64.9 | H7: 635.8 | I7: =_xlfn.XLOOKUP(B7,Orders_Data!A:A,Orders_Data!C:C,"Not Found") -> 15 | J7: =_xlfn.XLOOKUP(I7,Products_Data!A:A,Products_Data!C:C,"Not Found") -> Footwear | K7: =_xlfn.XLOOKUP(B7,Orders_Data!A:A,Orders_Data!B:B,"Not Found") -> 58
A8: 700007 | B8: 900032 | C8: 45630 | D8: Not as Described | E8: Approved | F8: 970 | G8: 133.49 | H8: 157.62 | I8: =_xlfn.XLOOKUP(B8,Orders_Data!A:A,Orders_Data!C:C,"Not Found") -> 4 | J8: =_xlfn.XLOOKUP(I8,Products_Data!A:A,Products_Data!C:C,"Not Found") -> Fashion & Apparel | K8: =_xlfn.XLOOKUP(B8,Orders_Data!A:A,Orders_Data!B:B,"Not Found") -> 228
A9: 700008 | B9: 900036 | C9: 45582 | D9: Not as Described | E9: Approved | F9: 2150 | G9: 143.1 | H9: 349.38 | I9: =_xlfn.XLOOKUP(B9,Orders_Data!A:A,Orders_Data!C:C,"Not Found") -> 7 | J9: =_xlfn.XLOOKUP(I9,Products_Data!A:A,Products_Data!C:C,"Not Found") -> Fashion & Apparel | K9: =_xlfn.XLOOKUP(B9,Orders_Data!A:A,Orders_Data!B:B,"Not Found") -> 540
A10: 700009 | B10: 900041 | C10: 45405 | D10: Size/Fit Issue | E10: Approved | F10: 5310 | G10: 102.81 | H10: 287.62 | I10: =_xlfn.XLOOKUP(B10,Orders_Data!A:A,Orders_Data!C:C,"Not Found") -> 3 | J10: =_xlfn.XLOOKUP(I10,Products_Data!A:A,Products_Data!C:C,"Not Found") -> Fashion & Apparel | K10: =_xlfn.XLOOKUP(B10,Orders_Data!A:A,Orders_Data!B:B,"Not Found") -> 481
A11: 700010 | B11: 900045 | C11: 45658 | D11: Size/Fit Issue | E11: Approved | F11: 970 | G11: 114.4 | H11: 157.62 | I11: =_xlfn.XLOOKUP(B11,Orders_Data!A:A,Orders_Data!C:C,"Not Found") -> 4 | J11: =_xlfn.XLOOKUP(I11,Products_Data!A:A,Products_Data!C:C,"Not Found") -> Fashion & Apparel | K11: =_xlfn.XLOOKUP(B11,Orders_Data!A:A,Orders_Data!B:B,"Not Found") -> 214
A12: 700011 | B12: 900051 | C12: 45666 | D12: Defective/Damaged | E12: Approved | F12: 740 | G12: 169.55 | H12: 107.3 | I12: =_xlfn.XLOOKUP(B12,Orders_Data!A:A,Orders_Data!C:C,"Not Found") -> 33 | J12: =_xlfn.XLOOKUP(I12,Products_Data!A:A,Products_Data!C:C,"Not Found") -> Beauty & Personal Care | K12: =_xlfn.XLOOKUP(B12,Orders_Data!A:A,Orders_Data!B:B,"Not Found") -> 403
A13: 700012 | B13: 900052 | C13: 45585 | D13: Size/Fit Issue | E13: Approved | F13: 3900 | G13: 133.64 | H13: 663 | I13: =_xlfn.XLOOKUP(B13,Orders_Data!A:A,Orders_Data!C:C,"Not Found") -> 16 | J13: =_xlfn.XLOOKUP(I13,Products_Data!A:A,Products_Data!C:C,"Not Found") -> Footwear | K13: =_xlfn.XLOOKUP(B13,Orders_Data!A:A,Orders_Data!B:B,"Not Found") -> 542
... A1677: 701676 | B1677: 908993 | C1677: 45544 | D1677: Size/Fit Issue | E1677: Approved | F1677: 2560 | G1677: 152.84 | H1677: 435.2 | I1677: =_xlfn.XLOOKUP(B1677,Orders_Data!A:A,Orders_Data!C:C,"Not Found") -> 11 | J1677: =_xlfn.XLOOKUP(I1677,Products_Data!A:A,Products_Data!C:C,"Not Found") -> Footwear | K1677: =_xlfn.XLOOKUP(B1677,Orders_Data!A:A,Orders_Data!B:B,"Not Found") -> 546

Sheet Returns_Clean
A1: return_id | B1: order_id | C1: return_date | D1: return_reason | E1: return_status | F1: refund_amount | G1: reverse_shipping_cost | H1: restocking_loss | I1: Total Return Cost
A2: 700025 | B2: 900131 | C2: 45588 | D2: Changed Mind | E2: Rejected | F2: 0 | G2: 114.01 | H2: 0 | I2: 114.01
A3: 700029 | B3: 900162 | C3: 45480 | D3: Wrong Item Delivered | E3: Rejected | F3: 0 | G3: 83.31 | H3: 0 | I3: 83.31
A4: 700032 | B4: 900176 | C4: 45737 | D4: Wrong Item Delivered | E4: Rejected | F4: 0 | G4: 77.94 | H4: 0 | I4: 77.94
A5: 700074 | B5: 900380 | C5: 45474 | D5: Size/Fit Issue | E5: Rejected | F5: 0 | G5: 167.17 | H5: 0 | I5: 167.17
A6: 700088 | B6: 900424 | C6: 45617 | D6: Defective/Damaged | E6: Rejected | F6: 0 | G6: 110.41 | H6: 0 | I6: 110.41
A7: 700099 | B7: 900479 | C7: 45550 | D7: Changed Mind | E7: Rejected | F7: 0 | G7: 106.82 | H7: 0 | I7: 106.82
A8: 700116 | B8: 900575 | C8: 45760 | D8: Size/Fit Issue | E8: Rejected | F8: 0 | G8: 141.55 | H8: 0 | I8: 141.55
A9: 700129 | B9: 900642 | C9: 45755 | D9: Size/Fit Issue | E9: Rejected | F9: 0 | G9: 145.77 | H9: 0 | I9: 145.77
A10: 700145 | B10: 900748 | C10: 45612 | D10: Defective/Damaged | E10: Rejected | F10: 0 | G10: 165.39 | H10: 0 | I10: 165.39
A11: 700148 | B11: 900751 | C11: 45620 | D11: Defective/Damaged | E11: Rejected | F11: 0 | G11: 91.37 | H11: 0 | I11: 91.37
A12: 700151 | B12: 900762 | C12: 45664 | D12: Changed Mind | E12: Rejected | F12: 0 | G12: 82.25 | H12: 0 | I12: 82.25
A13: 700160 | B13: 900821 | C13: 45657 | D13: Changed Mind | E13: Rejected | F13: 0 | G13: 142.24 | H13: 0 | I13: 142.24
... A1677: 701676 | B1677: 908993 | C1677: 45544 | D1677: Size/Fit Issue | E1677: Approved | F1677: 2560 | G1677: 152.84 | H1677: 435.2 | I1677: 3148.04

Sheet Customers_Data
A1: customer_id | B1: customer_name | C1: city | D1: signup_date | E1: is_serial_returner
A2: 1 | B2: Kiara Thomas | C2: Delhi NCR | D2: 45538 | E2: FALSE
A3: 2 | B3: Vikram Pai | C3: Mumbai | D3: 45710 | E3: FALSE
A4: 3 | B4: Arun Shetty | C4: Bangalore | D4: 45635 | E4: FALSE
A5: 4 | B5: Meera Bose | C5: Chennai | D5: 45668 | E5: FALSE
A6: 5 | B6: Arjun Bose | C6: Mumbai | D6: 45691 | E6: FALSE
A7: 6 | B7: Arjun Chatterjee | C7: Kochi | D7: 45383 | E7: FALSE
A8: 7 | B8: Deepa Pai | C8: Mumbai | D8: 45401 | E8: FALSE
A9: 8 | B9: Ananya Iyer | C9: Delhi NCR | D9: 45624 | E9: FALSE
A10: 9 | B10: Kavya Iyer | C10: Bangalore | D10: 45542 | E10: FALSE
A11: 10 | B11: Sanjay Reddy | C11: Pune | D11: 45447 | E11: FALSE
A12: 11 | B12: Kavya Gupta | C12: Hyderabad | D12: 45680 | E12: FALSE
A13: 12 | B13: Saanvi Sharma | C13: Pune | D13: 45598 | E13: FALSE
... A601: 600 | B601: Priya Joseph | C601: Mumbai | D601: 45462 | E601: FALSE

Sheet Return_Cost_Calculator
A1: RETURN COST CALCULATOR | H1: TOTAL RETURN COST | I1: =SUM(F4:F1679) -> 6959047.2
H2: AVERAGE RETURN COST | I2: =AVERAGE(F4:F1679) -> 4152.1761
A3: Return ID | B3: Order ID | C3: Refund Amount | D3: Reverse Shipping Cost | E3: Restocking Loss | F3: Total Return Cost | H3: TOTAL RETURNS | I3: =COUNTA(A4:A1679) -> 1676
A4: =Returns_Data!A2 -> 700001 | B4: =Returns_Data!B2 -> 900008 | C4: =Returns_Data!F2 -> 1130 | D4: =Returns_Data!G2 -> 81.79 | E4: =Returns_Data!H2 -> 175.15 | F4: =SUM(C4:E4) -> 1386.94
A5: =Returns_Data!A3 -> 700002 | B5: =Returns_Data!B3 -> 900010 | C5: =Returns_Data!F3 -> 590 | D5: =Returns_Data!G3 -> 111.34 | E5: =Returns_Data!H3 -> 85.55 | F5: =SUM(C5:E5) -> 786.89
A6: =Returns_Data!A4 -> 700003 | B6: =Returns_Data!B4 -> 900011 | C6: =Returns_Data!F4 -> 910 | D6: =Returns_Data!G4 -> 111.45 | E6: =Returns_Data!H4 -> 141.05 | F6: =SUM(C6:E6) -> 1162.5 | H6: Return Reason | I6: Total Return Cost
A7: =Returns_Data!A5 -> 700004 | B7: =Returns_Data!B5 -> 900017 | C7: =Returns_Data!F5 -> 3170 | D7: =Returns_Data!G5 -> 177.27 | E7: =Returns_Data!H5 -> 570.6 | F7: =SUM(C7:E7) -> 3917.87 | H7: Better Price Found | I7: =SUMIF(Returns_Data!D:D,H7,Returns_Data!F:F)+SUMIF(Returns_Data!D:D,H7,Returns_Data!G:G)+SUMIF(Returns_Data!D:D,H7,Returns_Data!H:H) -> 394162.82
A8: =Returns_Data!A6 -> 700005 | B8: =Returns_Data!B6 -> 900024 | C8: =Returns_Data!F6 -> 410 | D8: =Returns_Data!G6 -> 78.65 | E8: =Returns_Data!H6 -> 59.45 | F8: =SUM(C8:E8) -> 548.1 | H8: Changed Mind | I8: =SUMIF(Returns_Data!D:D,H8,Returns_Data!F:F)+SUMIF(Returns_Data!D:D,H8,Returns_Data!G:G)+SUMIF(Returns_Data!D:D,H8,Returns_Data!H:H) -> 1287960.3
A9: =Returns_Data!A7 -> 700006 | B9: =Returns_Data!B7 -> 900026 | C9: =Returns_Data!F7 -> 3740 | D9: =Returns_Data!G7 -> 64.9 | E9: =Returns_Data!H7 -> 635.8 | F9: =SUM(C9:E9) -> 4440.7 | H9: Defective/Damaged | I9: =SUMIF(Returns_Data!D:D,H9,Returns_Data!F:F)+SUMIF(Returns_Data!D:D,H9,Returns_Data!G:G)+SUMIF(Returns_Data!D:D,H9,Returns_Data!H:H) -> 2238263.2
A10: =Returns_Data!A8 -> 700007 | B10: =Returns_Data!B8 -> 900032 | C10: =Returns_Data!F8 -> 970 | D10: =Returns_Data!G8 -> 133.49 | E10: =Returns_Data!H8 -> 157.62 | F10: =SUM(C10:E10) -> 1261.11 | H10: Not as Described | I10: =SUMIF(Returns_Data!D:D,H10,Returns_Data!F:F)+SUMIF(Returns_Data!D:D,H10,Returns_Data!G:G)+SUMIF(Returns_Data!D:D,H10,Returns_Data!H:H) -> 1415301.7
A11: =Returns_Data!A9 -> 700008 | B11: =Returns_Data!B9 -> 900036 | C11: =Returns_Data!F9 -> 2150 | D11: =Returns_Data!G9 -> 143.1 | E11: =Returns_Data!H9 -> 349.38 | F11: =SUM(C11:E11) -> 2642.48 | H11: Size/Fit Issue | I11: =SUMIF(Returns_Data!D:D,H11,Returns_Data!F:F)+SUMIF(Returns_Data!D:D,H11,Returns_Data!G:G)+SUMIF(Returns_Data!D:D,H11,Returns_Data!H:H) -> 1472508.1
A12: =Returns_Data!A10 -> 700009 | B12: =Returns_Data!B10 -> 900041 | C12: =Returns_Data!F10 -> 5310 | D12: =Returns_Data!G10 -> 102.81 | E12: =Returns_Data!H10 -> 287.62 | F12: =SUM(C12:E12) -> 5700.43 | H12: Wrong Item Delivered | I12: =SUMIF(Returns_Data!D:D,H12,Returns_Data!F:F)+SUMIF(Returns_Data!D:D,H12,Returns_Data!G:G)+SUMIF(Returns_Data!D:D,H12,Returns_Data!H:H) -> 150850.96
A13: =Returns_Data!A11 -> 700010 | B13: =Returns_Data!B11 -> 900045 | C13: =Returns_Data!F11 -> 970 | D13: =Returns_Data!G11 -> 114.4 | E13: =Returns_Data!H11 -> 157.62 | F13: =SUM(C13:E13) -> 1242.02
A14: =Returns_Data!A12 -> 700011 | B14: =Returns_Data!B12 -> 900051 | C14: =Returns_Data!F12 -> 740 | D14: =Returns_Data!G12 -> 169.55 | E14: =Returns_Data!H12 -> 107.3 | F14: =SUM(C14:E14) -> 1016.85
A15: =Returns_Data!A13 -> 700012 | B15: =Returns_Data!B13 -> 900052 | C15: =Returns_Data!F13 -> 3900 | D15: =Returns_Data!G13 -> 133.64 | E15: =Returns_Data!H13 -> 663 | F15: =SUM(C15:E15) -> 4696.64 | H15: Product Category | I15: Total Return Cost
A16: =Returns_Data!A14 -> 700013 | B16: =Returns_Data!B14 -> 900055 | C16: =Returns_Data!F14 -> 1190 | D16: =Returns_Data!G14 -> 92.13 | E16: =Returns_Data!H14 -> 193.38 | F16: =SUM(C16:E16) -> 1475.51 | H16: Fashion & Apparel | I16: =SUMIF(Returns_Data!J:J,H16,Returns_Data!F:F)+SUMIF(Returns_Data!J:J,H16,Returns_Data!G:G)+SUMIF(Returns_Data!J:J,H16,Returns_Data!H:H) -> 929453.75
A17: =Returns_Data!A15 -> 700014 | B17: =Returns_Data!B15 -> 900056 | C17: =Returns_Data!F15 -> 1190 | D17: =Returns_Data!G15 -> 171.55 | E17: =Returns_Data!H15 -> 193.38 | F17: =SUM(C17:E17) -> 1554.93 | H17: Footwear | I17: =SUMIF(Returns_Data!J:J,H17,Returns_Data!F:F)+SUMIF(Returns_Data!J:J,H17,Returns_Data!G:G)+SUMIF(Returns_Data!J:J,H17,Returns_Data!H:H) -> 1674655.2
A18: =Returns_Data!A16 -> 700015 | B18: =Returns_Data!B16 -> 900060 | C18: =Returns_Data!F16 -> 1960 | D18: =Returns_Data!G16 -> 156.08 | E18: =Returns_Data!H16 -> 318.5 | F18: =SUM(C18:E18) -> 2434.58 | H18: Accessories | I18: =SUMIF(Returns_Data!J:J,H18,Returns_Data!F:F)+SUMIF(Returns_Data!J:J,H18,Returns_Data!G:G)+SUMIF(Returns_Data!J:J,H18,Returns_Data!H:H) -> 382571.24
A19: =Returns_Data!A17 -> 700016 | B19: =Returns_Data!B17 -> 900069 | C19: =Returns_Data!F17 -> 740 | D19: =Returns_Data!G17 -> 128.46 | E19: =Returns_Data!H17 -> 107.3 | F19: =SUM(C19:E19) -> 975.76 | H19: Home & Kitchen | I19: =SUMIF(Returns_Data!J:J,H19,Returns_Data!F:F)+SUMIF(Returns_Data!J:J,H19,Returns_Data!G:G)+SUMIF(Returns_Data!J:J,H19,Returns_Data!H:H) -> 765489.5
A20: =Returns_Data!A18 -> 700017 | B20: =Returns_Data!B18 -> 900077 | C20: =Returns_Data!F18 -> 3900 | D20: =Returns_Data!G18 -> 105.95 | E20: =Returns_Data!H18 -> 663 | F20: =SUM(C20:E20) -> 4668.95 | H20: Electronics | I20: =SUMIF(Returns_Data!J:J,H20,Returns_Data!F:F)+SUMIF(Returns_Data!J:J,H20,Returns_Data!G:G)+SUMIF(Returns_Data!J:J,H20,Returns_Data!H:H) -> 3015026.5
A21: =Returns_Data!A19 -> 700018 | B21: =Returns_Data!B19 -> 900083 | C21: =Returns_Data!F19 -> 810 | D21: =Returns_Data!G19 -> 67.46 | E21: =Returns_Data!H19 -> 125.55 | F21: =SUM(C21:E21) -> 1003.01 | H21: Beauty & Personal Care | I21: =SUMIF(Returns_Data!J:J,H21,Returns_Data!F:F)+SUMIF(Returns_Data!J:J,H21,Returns_Data!G:G)+SUMIF(Returns_Data!J:J,H21,Returns_Data!H:H) -> 191851.03
A22: =Returns_Data!A20 -> 700019 | B22: =Returns_Data!B20 -> 900089 | C22: =Returns_Data!F20 -> 2370 | D22: =Returns_Data!G20 -> 94.14 | E22: =Returns_Data!H20 -> 402.9 | F22: =SUM(C22:E22) -> 2867.04
A23: =Returns_Data!A21 -> 700020 | B23: =Returns_Data!B21 -> 900092 | C23: =Returns_Data!F21 -> 2250 | D23: =Returns_Data!G21 -> 129.81 | E23: =Returns_Data!H21 -> 405 | F23: =SUM(C23:E23) -> 2784.81
A24: =Returns_Data!A22 -> 700021 | B24: =Returns_Data!B22 -> 900106 | C24: =Returns_Data!F22 -> 910 | D24: =Returns_Data!G22 -> 152.61 | E24: =Returns_Data!H22 -> 141.05 | F24: =SUM(C24:E24) -> 1203.66 | H24: Customer ID | I24: Return Count | J24: Return Frequency Flag
A25: =Returns_Data!A23 -> 700022 | B25: =Returns_Data!B23 -> 900107 | C25: =Returns_Data!F23 -> 2250 | D25: =Returns_Data!G23 -> 139.92 | E25: =Returns_Data!H23 -> 405 | F25: =SUM(C25:E25) -> 2794.92 | H25: {=_xlfn.UNIQUE(Returns_Data!K2:K1677)} -> 562 | I25: =COUNTIF(Returns_Data!K:K,H25) -> 2 | J25: =IF(I25>=3,"High Return Frequency","Normal") -> Normal
A26: =Returns_Data!A24 -> 700023 | B26: =Returns_Data!B24 -> 900117 | C26: =Returns_Data!F24 -> 3480 | D26: =Returns_Data!G24 -> 62.38 | E26: =Returns_Data!H24 -> 313.2 | F26: =SUM(C26:E26) -> 3855.58 | H26: 36 | I26: =COUNTIF(Returns_Data!K:K,H26) -> 3 | J26: =IF(I26>=3,"High Return Frequency","Normal") -> High Return Frequency
A27: =Returns_Data!A25 -> 700024 | B27: =Returns_Data!B25 -> 900130 | C27: =Returns_Data!F25 -> 3020 | D27: =Returns_Data!G25 -> 176.98 | E27: =Returns_Data!H25 -> 245.38 | F27: =SUM(C27:E27) -> 3442.36 | H27: 152 | I27: =COUNTIF(Returns_Data!K:K,H27) -> 2 | J27: =IF(I27>=3,"High Return Frequency","Normal") -> Normal
A28: =Returns_Data!A26 -> 700025 | B28: =Returns_Data!B26 -> 900131 | C28: =Returns_Data!F26 -> 0 | D28: =Returns_Data!G26 -> 114.01 | E28: =Returns_Data!H26 -> 0 | F28: =SUM(C28:E28) -> 114.01 | H28: 107 | I28: =COUNTIF(Returns_Data!K:K,H28) -> 4 | J28: =IF(I28>=3,"High Return Frequency","Normal") -> High Return Frequency
A29: =Returns_Data!A27 -> 700026 | B29: =Returns_Data!B27 -> 900143 | C29: =Returns_Data!F27 -> 1990 | D29: =Returns_Data!G27 -> 69.78 | E29: =Returns_Data!H27 -> 358.2 | F29: =SUM(C29:E29) -> 2417.98 | H29: 347 | I29: =COUNTIF(Returns_Data!K:K,H29) -> 4 | J29: =IF(I29>=3,"High Return Frequency","Normal") -> High Return Frequency
A30: =Returns_Data!A28 -> 700027 | B30: =Returns_Data!B28 -> 900154 | C30: =Returns_Data!F28 -> 510 | D30: =Returns_Data!G28 -> 105.82 | E30: =Returns_Data!H28 -> 73.95 | F30: =SUM(C30:E30) -> 689.77 | H30: 58 | I30: =COUNTIF(Returns_Data!K:K,H30) -> 4 | J30: =IF(I30>=3,"High Return Frequency","Normal") -> High Return Frequency
A31: =Returns_Data!A29 -> 700028 | B31: =Returns_Data!B29 -> 900155 | C31: =Returns_Data!F29 -> 1110 | D31: =Returns_Data!G29 -> 127.5 | E31: =Returns_Data!H29 -> 180.38 | F31: =SUM(C31:E31) -> 1417.88 | H31: 228 | I31: =COUNTIF(Returns_Data!K:K,H31) -> 4 | J31: =IF(I31>=3,"High Return Frequency","Normal") -> High Return Frequency
A32: =Returns_Data!A30 -> 700029 | B32: =Returns_Data!B30 -> 900162 | C32: =Returns_Data!F30 -> 0 | D32: =Returns_Data!G30 -> 83.31 | E32: =Returns_Data!H30 -> 0 | F32: =SUM(C32:E32) -> 83.31 | H32: 540 | I32: =COUNTIF(Returns_Data!K:K,H32) -> 3 | J32: =IF(I32>=3,"High Return Frequency","Normal") -> High Return Frequency
A33: =Returns_Data!A31 -> 700030 | B33: =Returns_Data!B31 -> 900168 | C33: =Returns_Data!F31 -> 1130 | D33: =Returns_Data!G31 -> 166.65 | E33: =Returns_Data!H31 -> 175.15 | F33: =SUM(C33:E33) -> 1471.8 | H33: 481 | I33: =COUNTIF(Returns_Data!K:K,H33) -> 5 | J33: =IF(I33>=3,"High Return Frequency","Normal") -> High Return Frequency
A34: =Returns_Data!A32 -> 700031 | B34: =Returns_Data!B32 -> 900170 | C34: =Returns_Data!F32 -> 1990 | D34: =Returns_Data!G32 -> 153.41 | E34: =Returns_Data!H32 -> 358.2 | F34: =SUM(C34:E34) -> 2501.61 | H34: 214 | I34: =COUNTIF(Returns_Data!K:K,H34) -> 3 | J34: =IF(I34>=3,"High Return Frequency","Normal") -> High Return Frequency
A35: =Returns_Data!A33 -> 700032 | B35: =Returns_Data!B33 -> 900176 | C35: =Returns_Data!F33 -> 0 | D35: =Returns_Data!G33 -> 77.94 | E35: =Returns_Data!H33 -> 0 | F35: =SUM(C35:E35) -> 77.94 | H35: 403 | I35: =COUNTIF(Returns_Data!K:K,H35) -> 2 | J35: =IF(I35>=3,"High Return Frequency","Normal") -> Normal
A36: =Returns_Data!A34 -> 700033 | B36: =Returns_Data!B34 -> 900178 | C36: =Returns_Data!F34 -> 9000 | D36: =Returns_Data!G34 -> 124.09 | E36: =Returns_Data!H34 -> 510 | F36: =SUM(C36:E36) -> 9634.09 | H36: 542 | I36: =COUNTIF(Returns_Data!K:K,H36) -> 10 | J36: =IF(I36>=3,"High Return Frequency","Normal") -> High Return Frequency
A37: =Returns_Data!A35 -> 700034 | B37: =Returns_Data!B35 -> 900188 | C37: =Returns_Data!F35 -> 4680 | D37: =Returns_Data!G35 -> 178.61 | E37: =Returns_Data!H35 -> 241.8 | F37: =SUM(C37:E37) -> 5100.41 | H37: 148 | I37: =COUNTIF(Returns_Data!K:K,H37) -> 2 | J37: =IF(I37>=3,"High Return Frequency","Normal") -> Normal
... A588: =Returns_Data!A586 -> 700585 | B588: =Returns_Data!B586 -> 902955 | C588: =Returns_Data!F586 -> 1870 | D588: =Returns_Data!G586 -> 132.67 | E588: =Returns_Data!H586 -> 303.88 | F588: =SUM(C588:E588) -> 2306.55 | H588: 61 | I588: =COUNTIF(Returns_Data!K:K,H588) -> 1 | J588: =IF(I588>=3,"High Return Frequency","Normal") -> Normal
A589: =Returns_Data!A587 -> 700586 | B589: =Returns_Data!B587 -> 902969 | C589: =Returns_Data!F587 -> 2150 | D589: =Returns_Data!G587 -> 65.3 | E589: =Returns_Data!H587 -> 349.38 | F589: =SUM(C589:E589) -> 2564.68 | I589: =COUNTIF(Returns_Data!K:K,H589) -> 0 | J589: =IF(I589>=3,"High Return Frequency","Normal") -> Normal
A590: =Returns_Data!A588 -> 700587 | B590: =Returns_Data!B588 -> 902972 | C590: =Returns_Data!F588 -> 3740 | D590: =Returns_Data!G588 -> 127.24 | E590: =Returns_Data!H588 -> 635.8 | F590: =SUM(C590:E590) -> 4503.04 | I590: =COUNTIF(Returns_Data!K:K,H590) -> 0 | J590: =IF(I590>=3,"High Return Frequency","Normal") -> Normal
...

Sheet Orders_Data
A1: order_id | B1: customer_id | C1: product_id | D1: order_date | E1: delivery_date | F1: city | G1: category | H1: payment_method | I1: quantity | J1: order_amount
A2: 900001 | B2: 258 | C2: 28 | D2: 45681 | E2: 45684 | F2: Delhi NCR | G2: Home & Kitchen | H2: Prepaid | I2: 1 | J2: 3170
A3: 900002 | B3: 407 | C3: 43 | D3: 45740 | E3: 45744 | F3: Mumbai | G3: Accessories | H3: Prepaid | I3: 1 | J3: 910
A4: 900003 | B4: 595 | C4: 14 | D4: 45599 | E4: 45601 | F4: Delhi NCR | G4: Footwear | H4: Prepaid | I4: 1 | J4: 2370
A5: 900004 | B5: 512 | C5: 14 | D5: 45565 | E5: 45568 | F5: Kochi | G5: Footwear | H5: COD | I5: 3 | J5: 7110
A6: 900005 | B6: 304 | C6: 34 | D6: 45479 | E6: 45482 | F6: Pune | G6: Beauty & Personal Care | H6: Prepaid | I6: 1 | J6: 410
A7: 900006 | B7: 206 | C7: 27 | D7: 45533 | E7: 45538 | F7: Chennai | G7: Home & Kitchen | H7: Prepaid | I7: 1 | J7: 1080
A8: 900007 | B8: 371 | C8: 33 | D8: 45667 | E8: 45670 | F8: Bangalore | G8: Beauty & Personal Care | H8: Prepaid | I8: 1 | J8: 740
A9: 900008 | B9: 562 | C9: 44 | D9: 45416 | E9: 45419 | F9: Kochi | G9: Accessories | H9: COD | I9: 1 | J9: 1130
A10: 900009 | B10: 372 | C10: 48 | D10: 45503 | E10: 45507 | F10: Bangalore | G10: Accessories | H10: Prepaid | I10: 1 | J10: 1560
A11: 900010 | B11: 36 | C11: 35 | D11: 45532 | E11: 45538 | F11: Pune | G11: Beauty & Personal Care | H11: COD | I11: 1 | J11: 590
A12: 900011 | B12: 152 | C12: 43 | D12: 45451 | E12: 45453 | F12: Hyderabad | G12: Accessories | H12: Prepaid | I12: 1 | J12: 910
A13: 900012 | B13: 206 | C13: 17 | D13: 45709 | E13: 45714 | F13: Chennai | G13: Electronics | H13: Prepaid | I13: 1 | J13: 13790
... A9001: 909000 | B9001: 46 | C9001: 39 | D9001: 45698 | E9001: 45704 | F9001: Bangalore | G9001: Beauty & Personal Care | H9001: COD | I9001: 1 | J9001: 780

Sheet Products_Data
A1: product_id | B1: product_name | C1: category | D1: price | E1: cost
A2: 1 | B2: Fashion Item 1 | C2: Fashion & Apparel | D2: 1110 | E2: 721.5
A3: 2 | B3: Fashion Item 2 | C3: Fashion & Apparel | D3: 1190 | E3: 773.5
A4: 3 | B4: Fashion Item 3 | C4: Fashion & Apparel | D4: 1770 | E4: 1150.5
A5: 4 | B5: Fashion Item 4 | C5: Fashion & Apparel | D5: 970 | E5: 630.5
A6: 5 | B6: Fashion Item 5 | C6: Fashion & Apparel | D6: 1960 | E6: 1274
A7: 6 | B7: Fashion Item 6 | C7: Fashion & Apparel | D7: 1510 | E7: 981.5
A8: 7 | B8: Fashion Item 7 | C8: Fashion & Apparel | D8: 2150 | E8: 1397.5
A9: 8 | B9: Fashion Item 8 | C9: Fashion & Apparel | D9: 1870 | E9: 1215.5
A10: 9 | B10: Footwear Item 1 | C10: Footwear | D10: 3370 | E10: 2291.6
A11: 10 | B11: Footwear Item 2 | C11: Footwear | D11: 3700 | E11: 2516
A12: 11 | B12: Footwear Item 3 | C12: Footwear | D12: 2560 | E12: 1740.8
A13: 12 | B13: Footwear Item 4 | C13: Footwear | D13: 2600 | E13: 1768
... A49: 48 | B49: Accessories Item 8 | C49: Accessories | D49: 1560 | E49: 967.2
